<?xml version="1.0" ?>
<!-- =================================================================================== -->
<!-- |    This document was autogenerated by xacro from my_robot.xacro                 | -->
<!-- |    EDITING THIS FILE BY HAND IS NOT RECOMMENDED                                 | -->
<!-- =================================================================================== -->
<robot name="my_car">
  <!-- ==== Colors ==== -->
  <material name="gray">
    <color rgba="0.5 0.5 0.5 1"/>
  </material>
  <material name="black">
    <color rgba="0 0 0 1"/>
  </material>
  <material name="blue">
    <color rgba="0 0 1 1"/>
  </material>
  <material name="red">
    <color rgba="1 0 0 1"/>
  </material>
  <material name="green">
    <color rgba="0 1 0 1"/>
  </material>
  <!-- ==== Base Link ==== -->
  <link name="base_link">
    <visual>
      <geometry>
        <box size="0.6 0.4 0.1"/>
      </geometry>
      <material name="gray"/>
    </visual>
  </link>
  <link name="left_front_wheel">
    <visual>
      <geometry>
        <cylinder length="0.03" radius="0.05"/>
      </geometry>
      <origin rpy="1.5708 0 0" xyz="0.25 -0.18 -0.05"/>
      <material name="black"/>
    </visual>
  </link>
  <joint name="left_front_wheel_joint" type="continuous">
    <parent link="base_link"/>
    <child link="left_front_wheel"/>
    <origin rpy="0 0 0" xyz="0.25 -0.18 -0.05"/>
    <axis xyz="0 1 0"/>
  </joint>
  <link name="right_front_wheel">
    <visual>
      <geometry>
        <cylinder length="0.03" radius="0.05"/>
      </geometry>
      <origin rpy="1.5708 0 0" xyz="0.25 0.18 -0.05"/>
      <material name="black"/>
    </visual>
  </link>
  <joint name="right_front_wheel_joint" type="continuous">
    <parent link="base_link"/>
    <child link="right_front_wheel"/>
    <origin rpy="0 0 0" xyz="0.25 0.18 -0.05"/>
    <axis xyz="0 1 0"/>
  </joint>
  <link name="left_rear_wheel">
    <visual>
      <geometry>
        <cylinder length="0.03" radius="0.05"/>
      </geometry>
      <origin rpy="1.5708 0 0" xyz="-0.25 -0.18 -0.05"/>
      <material name="black"/>
    </visual>
  </link>
  <joint name="left_rear_wheel_joint" type="continuous">
    <parent link="base_link"/>
    <child link="left_rear_wheel"/>
    <origin rpy="0 0 0" xyz="-0.25 -0.18 -0.05"/>
    <axis xyz="0 1 0"/>
  </joint>
  <link name="right_rear_wheel">
    <visual>
      <geometry>
        <cylinder length="0.03" radius="0.05"/>
      </geometry>
      <origin rpy="1.5708 0 0" xyz="-0.25 0.18 -0.05"/>
      <material name="black"/>
    </visual>
  </link>
  <joint name="right_rear_wheel_joint" type="continuous">
    <parent link="base_link"/>
    <child link="right_rear_wheel"/>
    <origin rpy="0 0 0" xyz="-0.25 0.18 -0.05"/>
    <axis xyz="0 1 0"/>
  </joint>
  <!-- ==== Camera ==== -->
  <link name="camera_link">
    <visual>
      <geometry>
        <box size="0.05 0.03 0.03"/>
      </geometry>
      <origin rpy="0 0 0" xyz="0.3 0 0.1"/>
      <material name="blue"/>
    </visual>
  </link>
  <joint name="camera_joint" type="fixed">
    <parent link="base_link"/>
    <child link="camera_link"/>
    <origin rpy="0 0 0" xyz="0.3 0 0.1"/>
  </joint>
  <!-- ==== Lidar ==== -->
  <link name="lidar_link">
    <visual>
      <geometry>
        <cylinder length="0.02" radius="0.05"/>
      </geometry>
      <origin rpy="0 0 0" xyz="0 0 0.08"/>
      <material name="red"/>
    </visual>
  </link>
  <joint name="lidar_joint" type="fixed">
    <parent link="base_link"/>
    <child link="lidar_link"/>
    <origin rpy="0 0 0" xyz="0 0 0.08"/>
  </joint>
  <!-- ==== IMU ==== -->
  <link name="imu_link">
    <visual>
      <geometry>
        <box size="0.03 0.03 0.02"/>
      </geometry>
      <origin rpy="0 0 0" xyz="0 0 0.02"/>
      <material name="green"/>
    </visual>
  </link>
  <joint name="imu_joint" type="fixed">
    <parent link="base_link"/>
    <child link="imu_link"/>
    <origin rpy="0 0 0" xyz="0 0 0.02"/>
  </joint>
</robot>
